Workbook
Name Slicer_Đối_tượng_KH: #N/A
Name Slicer_Lĩnh_vực: #N/A
Name Slicer_Năm: #N/A
Name Slicer_Tháng: #N/A

Sheet Báo cáo

Sheet Data
A1: Tỉnh | B1: Đối tác/Khách hàng | C1: Lĩnh vực | D1: Giá trị nguồn việc | E1: Ngày ký HĐ | F1: Tháng | G1: Năm | H1: Vùng miền | I1: Đối tượng KH | J1: Hình thức | K1: Mã sản phẩm | L1: Nguồn việc | O1: Data gốc
A2: NAN | B2: BỆNH VIỆN ĐA KHOA DIỄN CHÂU | C2: ICT | D2: 29360909 | E2: 45292 | F2: =MONTH(Data!$E2) -> 1 | G2: =YEAR(Data!$E2) -> 2024 | H2: Bắc Trung Bộ | I2: =IF(ISNUMBER(SEARCH("Công ty",$B2)),"Doanh nghiệp",IF(ISNUMBER(SEARCH("Doanh nghiệp",$B2)),"Doanh nghiệp",IF(ISNUMBER(SEARCH("Tập đoàn",$B2)),"Doanh nghiệp", IF(ISNUMBER(SEARCH("Bệnh viện",$B2)),"Bệnh viện", IF(ISNUMBER(SEARCH("Ngân hàng",$B2)),"Ngân hàng",IF(ISNUMBER(SEARCH("trường",$B2)),"Trường học",IF(ISNUMBER(SEARCH("học viện",$B2)),"Trường học", IF(ISNUMBER(SEARCH("Bộ",$B2)),"Sở ban ngành",IF(ISNUMBER(SEARCH("Đoàn",$B2)),"Sở ban ngành",IF(ISNUMBER(SEARCH("Phòng",$B2)),"Sở ban ngành",IF(ISNUMBER(SEARCH("UBND",$B2)),"Sở ban ngành",IF(ISNUMBER(SEARCH("ủy ban",$B2)),"Sở ban ngành",IF(ISNUMBER(SEARCH("công an",$B2)),"Sở ban ngành",IF(ISNUMBER(SEARCH("sở",$B2)),"Sở ban ngành",IF(ISNUMBER(SEARCH("thôn",$B2)),"Sở ban ngành",IF(ISNUMBER(SEARCH("xã",$B2)),"Sở ban ngành",IF(ISNUMBER(SEARCH("quân khu",$B2)),"Sở ban ngành",IF(ISNUMBER(SEARCH("cục",$B2)),"Sở ban ngành",IF(ISNUMBER(SEARCH("viện",$B2)),"Sở ban ngành",IF(ISNUMBER(SEARCH("quỹ",$B2)),"Sở ban ngành",IF(ISNUMBER(SEARCH("trung tâm",$B2)),"Sở ban ngành",IF(ISNUMBER(SEARCH("quân chủng",$B2)),"Sở ban ngành",IF(ISNUMBER(SEARCH("hội",$B2)),"Sở ban ngành", "Khác"))))))))))))))))))))))) -> Bệnh viện | J2: Digital Marketing | K2: A | L2: =Data!$D2/10^6 -> 29.360909 | O2: Fix Data
A3: BDH | B3: BỆNH VIỆN ĐA KHOA TỈNH BÌNH ĐỊNH | C3: ICT | D3: 8842364 | E3: 45292 | F3: =MONTH(Data!$E3) -> 1 | G3: =YEAR(Data!$E3) -> 2024 | H3: Duyên hải Nam Trung Bộ | I3: =IF(ISNUMBER(SEARCH("Công ty",$B3)),"Doanh nghiệp",IF(ISNUMBER(SEARCH("Doanh nghiệp",$B3)),"Doanh nghiệp",IF(ISNUMBER(SEARCH("Tập đoàn",$B3)),"Doanh nghiệp", IF(ISNUMBER(SEARCH("Bệnh viện",$B3)),"Bệnh viện", IF(ISNUMBER(SEARCH("Ngân hàng",$B3)),"Ngân hàng",IF(ISNUMBER(SEARCH("trường",$B3)),"Trường học",IF(ISNUMBER(SEARCH("học viện",$B3)),"Trường học", IF(ISNUMBER(SEARCH("Bộ",$B3)),"Sở ban ngành",IF(ISNUMBER(SEARCH("Đoàn",$B3)),"Sở ban ngành",IF(ISNUMBER(SEARCH("Phòng",$B3)),"Sở ban ngành",IF(ISNUMBER(SEARCH("UBND",$B3)),"Sở ban ngành",IF(ISNUMBER(SEARCH("ủy ban",$B3)),"Sở ban ngành",IF(ISNUMBER(SEARCH("công an",$B3)),"Sở ban ngành",IF(ISNUMBER(SEARCH("sở",$B3)),"Sở ban ngành",IF(ISNUMBER(SEARCH("thôn",$B3)),"Sở ban ngành",IF(ISNUMBER(SEARCH("xã",$B3)),"Sở ban ngành",IF(ISNUMBER(SEARCH("quân khu",$B3)),"Sở ban ngành",IF(ISNUMBER(SEARCH("cục",$B3)),"Sở ban ngành",IF(ISNUMBER(SEARCH("viện",$B3)),"Sở ban ngành",IF(ISNUMBER(SEARCH("quỹ",$B3)),"Sở ban ngành",IF(ISNUMBER(SEARCH("trung tâm",$B3)),"Sở ban ngành",IF(ISNUMBER(SEARCH("quân chủng",$B3)),"Sở ban ngành",IF(ISNUMBER(SEARCH("hội",$B3)),"Sở ban ngành", "Khác"))))))))))))))))))))))) -> Bệnh viện | J3: Bán hàng trực tiếp | K3: B | L3: =Data!$D3/10^6 -> 8.842364
A4: CTO | B4: BỆNH VIỆN QUÂN Y 121 | C4: ME | D4: 81100000 | E4: 45292 | F4: =MONTH(Data!$E4) -> 1 | G4: =YEAR(Data!$E4) -> 2024 | H4: ĐB Sông Cửu Long | I4: =IF(ISNUMBER(SEARCH("Công ty",$B4)),"Doanh nghiệp",IF(ISNUMBER(SEARCH("Doanh nghiệp",$B4)),"Doanh nghiệp",IF(ISNUMBER(SEARCH("Tập đoàn",$B4)),"Doanh nghiệp", IF(ISNUMBER(SEARCH("Bệnh viện",$B4)),"Bệnh viện", IF(ISNUMBER(SEARCH("Ngân hàng",$B4)),"Ngân hàng",IF(ISNUMBER(SEARCH("trường",$B4)),"Trường học",IF(ISNUMBER(SEARCH("học viện",$B4)),"Trường học", IF(ISNUMBER(SEARCH("Bộ",$B4)),"Sở ban ngành",IF(ISNUMBER(SEARCH("Đoàn",$B4)),"Sở ban ngành",IF(ISNUMBER(SEARCH("Phòng",$B4)),"Sở ban ngành",IF(ISNUMBER(SEARCH("UBND",$B4)),"Sở ban ngành",IF(ISNUMBER(SEARCH("ủy ban",$B4)),"Sở ban ngành",IF(ISNUMBER(SEARCH("công an",$B4)),"Sở ban ngành",IF(ISNUMBER(SEARCH("sở",$B4)),"Sở ban ngành",IF(ISNUMBER(SEARCH("thôn",$B4)),"Sở ban ngành",IF(ISNUMBER(SEARCH("xã",$B4)),"Sở ban ngành",IF(ISNUMBER(SEARCH("quân khu",$B4)),"Sở ban ngành",IF(ISNUMBER(SEARCH("cục",$B4)),"Sở ban ngành",IF(ISNUMBER(SEARCH("viện",$B4)),"Sở ban ngành",IF(ISNUMBER(SEARCH("quỹ",$B4)),"Sở ban ngành",IF(ISNUMBER(SEARCH("trung tâm",$B4)),"Sở ban ngành",IF(ISNUMBER(SEARCH("quân chủng",$B4)),"Sở ban ngành",IF(ISNUMBER(SEARCH("hội",$B4)),"Sở ban ngành", "Khác"))))))))))))))))))))))) -> Bệnh viện | J4: Digital Marketing | K4: C | L4: =Data!$D4/10^6 -> 81.1
A5: LAN | B5: Công ty 1 | C5: ICT | D5: 45000000 | E5: 45292 | F5: =MONTH(Data!$E5) -> 1 | G5: =YEAR(Data!$E5) -> 2024 | H5: ĐB Sông Cửu Long | I5: =IF(ISNUMBER(SEARCH("Công ty",$B5)),"Doanh nghiệp",IF(ISNUMBER(SEARCH("Doanh nghiệp",$B5)),"Doanh nghiệp",IF(ISNUMBER(SEARCH("Tập đoàn",$B5)),"Doanh nghiệp", IF(ISNUMBER(SEARCH("Bệnh viện",$B5)),"Bệnh viện", IF(ISNUMBER(SEARCH("Ngân hàng",$B5)),"Ngân hàng",IF(ISNUMBER(SEARCH("trường",$B5)),"Trường học",IF(ISNUMBER(SEARCH("học viện",$B5)),"Trường học", IF(ISNUMBER(SEARCH("Bộ",$B5)),"Sở ban ngành",IF(ISNUMBER(SEARCH("Đoàn",$B5)),"Sở ban ngành",IF(ISNUMBER(SEARCH("Phòng",$B5)),"Sở ban ngành",IF(ISNUMBER(SEARCH("UBND",$B5)),"Sở ban ngành",IF(ISNUMBER(SEARCH("ủy ban",$B5)),"Sở ban ngành",IF(ISNUMBER(SEARCH("công an",$B5)),"Sở ban ngành",IF(ISNUMBER(SEARCH("sở",$B5)),"Sở ban ngành",IF(ISNUMBER(SEARCH("thôn",$B5)),"Sở ban ngành",IF(ISNUMBER(SEARCH("xã",$B5)),"Sở ban ngành",IF(ISNUMBER(SEARCH("quân khu",$B5)),"Sở ban ngành",IF(ISNUMBER(SEARCH("cục",$B5)),"Sở ban ngành",IF(ISNUMBER(SEARCH("viện",$B5)),"Sở ban ngành",IF(ISNUMBER(SEARCH("quỹ",$B5)),"Sở ban ngành",IF(ISNUMBER(SEARCH("trung tâm",$B5)),"Sở ban ngành",IF(ISNUMBER(SEARCH("quân chủng",$B5)),"Sở ban ngành",IF(ISNUMBER(SEARCH("hội",$B5)),"Sở ban ngành", "Khác"))))))))))))))))))))))) -> Doanh nghiệp | J5: Bán hàng trực tiếp | K5: B | L5: =Data!$D5/10^6 -> 45
A6: TNH | B6: Công ty 6 | C6: ICT | D6: 79329245 | E6: 45292 | F6: =MONTH(Data!$E6) -> 1 | G6: =YEAR(Data!$E6) -> 2024 | H6: Đông Nam Bộ | I6: =IF(ISNUMBER(SEARCH("Công ty",$B6)),"Doanh nghiệp",IF(ISNUMBER(SEARCH("Doanh nghiệp",$B6)),"Doanh nghiệp",IF(ISNUMBER(SEARCH("Tập đoàn",$B6)),"Doanh nghiệp", IF(ISNUMBER(SEARCH("Bệnh viện",$B6)),"Bệnh viện", IF(ISNUMBER(SEARCH("Ngân hàng",$B6)),"Ngân hàng",IF(ISNUMBER(SEARCH("trường",$B6)),"Trường học",IF(ISNUMBER(SEARCH("học viện",$B6)),"Trường học", IF(ISNUMBER(SEARCH("Bộ",$B6)),"Sở ban ngành",IF(ISNUMBER(SEARCH("Đoàn",$B6)),"Sở ban ngành",IF(ISNUMBER(SEARCH("Phòng",$B6)),"Sở ban ngành",IF(ISNUMBER(SEARCH("UBND",$B6)),"Sở ban ngành",IF(ISNUMBER(SEARCH("ủy ban",$B6)),"Sở ban ngành",IF(ISNUMBER(SEARCH("công an",$B6)),"Sở ban ngành",IF(ISNUMBER(SEARCH("sở",$B6)),"Sở ban ngành",IF(ISNUMBER(SEARCH("thôn",$B6)),"Sở ban ngành",IF(ISNUMBER(SEARCH("xã",$B6)),"Sở ban ngành",IF(ISNUMBER(SEARCH("quân khu",$B6)),"Sở ban ngành",IF(ISNUMBER(SEARCH("cục",$B6)),"Sở ban ngành",IF(ISNUMBER(SEARCH("viện",$B6)),"Sở ban ngành",IF(ISNUMBER(SEARCH("quỹ",$B6)),"Sở ban ngành",IF(ISNUMBER(SEARCH("trung tâm",$B6)),"Sở ban ngành",IF(ISNUMBER(SEARCH("quân chủng",$B6)),"Sở ban ngành",IF(ISNUMBER(SEARCH("hội",$B6)),"Sở ban ngành", "Khác"))))))))))))))))))))))) -> Doanh nghiệp | J6: Digital Marketing | K6: A | L6: =Data!$D6/10^6 -> 79.329245
A7: BPC | B7: Công ty 7 | C7: ICT | D7: 14434041 | E7: 45292 | F7: =MONTH(Data!$E7) -> 1 | G7: =YEAR(Data!$E7) -> 2024 | H7: Đông Nam Bộ | I7: =IF(ISNUMBER(SEARCH("Công ty",$B7)),"Doanh nghiệp",IF(ISNUMBER(SEARCH("Doanh nghiệp",$B7)),"Doanh nghiệp",IF(ISNUMBER(SEARCH("Tập đoàn",$B7)),"Doanh nghiệp", IF(ISNUMBER(SEARCH("Bệnh viện",$B7)),"Bệnh viện", IF(ISNUMBER(SEARCH("Ngân hàng",$B7)),"Ngân hàng",IF(ISNUMBER(SEARCH("trường",$B7)),"Trường học",IF(ISNUMBER(SEARCH("học viện",$B7)),"Trường học", IF(ISNUMBER(SEARCH("Bộ",$B7)),"Sở ban ngành",IF(ISNUMBER(SEARCH("Đoàn",$B7)),"Sở ban ngành",IF(ISNUMBER(SEARCH("Phòng",$B7)),"Sở ban ngành",IF(ISNUMBER(SEARCH("UBND",$B7)),"Sở ban ngành",IF(ISNUMBER(SEARCH("ủy ban",$B7)),"Sở ban ngành",IF(ISNUMBER(SEARCH("công an",$B7)),"Sở ban ngành",IF(ISNUMBER(SEARCH("sở",$B7)),"Sở ban ngành",IF(ISNUMBER(SEARCH("thôn",$B7)),"Sở ban ngành",IF(ISNUMBER(SEARCH("xã",$B7)),"Sở ban ngành",IF(ISNUMBER(SEARCH("quân khu",$B7)),"Sở ban ngành",IF(ISNUMBER(SEARCH("cục",$B7)),"Sở ban ngành",IF(ISNUMBER(SEARCH("viện",$B7)),"Sở ban ngành",IF(ISNUMBER(SEARCH("quỹ",$B7)),"Sở ban ngành",IF(ISNUMBER(SEARCH("trung tâm",$B7)),"Sở ban ngành",IF(ISNUMBER(SEARCH("quân chủng",$B7)),"Sở ban ngành",IF(ISNUMBER(SEARCH("hội",$B7)),"Sở ban ngành", "Khác"))))))))))))))))))))))) -> Doanh nghiệp | J7: Bán hàng trực tiếp | K7: A | L7: =Data!$D7/10^6 -> 14.434041
A8: BPC | B8: Công ty 8 | C8: ICT | D8: 21437000 | E8: 45292 | F8: =MONTH(Data!$E8) -> 1 | G8: =YEAR(Data!$E8) -> 2024 | H8: Đông Nam Bộ | I8: =IF(ISNUMBER(SEARCH("Công ty",$B8)),"Doanh nghiệp",IF(ISNUMBER(SEARCH("Doanh nghiệp",$B8)),"Doanh nghiệp",IF(ISNUMBER(SEARCH("Tập đoàn",$B8)),"Doanh nghiệp", IF(ISNUMBER(SEARCH("Bệnh viện",$B8)),"Bệnh viện", IF(ISNUMBER(SEARCH("Ngân hàng",$B8)),"Ngân hàng",IF(ISNUMBER(SEARCH("trường",$B8)),"Trường học",IF(ISNUMBER(SEARCH("học viện",$B8)),"Trường học", IF(ISNUMBER(SEARCH("Bộ",$B8)),"Sở ban ngành",IF(ISNUMBER(SEARCH("Đoàn",$B8)),"Sở ban ngành",IF(ISNUMBER(SEARCH("Phòng",$B8)),"Sở ban ngành",IF(ISNUMBER(SEARCH("UBND",$B8)),"Sở ban ngành",IF(ISNUMBER(SEARCH("ủy ban",$B8)),"Sở ban ngành",IF(ISNUMBER(SEARCH("công an",$B8)),"Sở ban ngành",IF(ISNUMBER(SEARCH("sở",$B8)),"Sở ban ngành",IF(ISNUMBER(SEARCH("thôn",$B8)),"Sở ban ngành",IF(ISNUMBER(SEARCH("xã",$B8)),"Sở ban ngành",IF(ISNUMBER(SEARCH("quân khu",$B8)),"Sở ban ngành",IF(ISNUMBER(SEARCH("cục",$B8)),"Sở ban ngành",IF(ISNUMBER(SEARCH("viện",$B8)),"Sở ban ngành",IF(ISNUMBER(SEARCH("quỹ",$B8)),"Sở ban ngành",IF(ISNUMBER(SEARCH("trung tâm",$B8)),"Sở ban ngành",IF(ISNUMBER(SEARCH("quân chủng",$B8)),"Sở ban ngành",IF(ISNUMBER(SEARCH("hội",$B8)),"Sở ban ngành", "Khác"))))))))))))))))))))))) -> Doanh nghiệp | J8: Digital Marketing | K8: A | L8: =Data!$D8/10^6 -> 21.437
A9: PTO | B9: Công ty 16 | C9: ICT | D9: 108855000 | E9: 45292 | F9: =MONTH(Data!$E9) -> 1 | G9: =YEAR(Data!$E9) -> 2024 | H9: Đông Bắc Bộ | I9: =IF(ISNUMBER(SEARCH("Công ty",$B9)),"Doanh nghiệp",IF(ISNUMBER(SEARCH("Doanh nghiệp",$B9)),"Doanh nghiệp",IF(ISNUMBER(SEARCH("Tập đoàn",$B9)),"Doanh nghiệp", IF(ISNUMBER(SEARCH("Bệnh viện",$B9)),"Bệnh viện", IF(ISNUMBER(SEARCH("Ngân hàng",$B9)),"Ngân hàng",IF(ISNUMBER(SEARCH("trường",$B9)),"Trường học",IF(ISNUMBER(SEARCH("học viện",$B9)),"Trường học", IF(ISNUMBER(SEARCH("Bộ",$B9)),"Sở ban ngành",IF(ISNUMBER(SEARCH("Đoàn",$B9)),"Sở ban ngành",IF(ISNUMBER(SEARCH("Phòng",$B9)),"Sở ban ngành",IF(ISNUMBER(SEARCH("UBND",$B9)),"Sở ban ngành",IF(ISNUMBER(SEARCH("ủy ban",$B9)),"Sở ban ngành",IF(ISNUMBER(SEARCH("công an",$B9)),"Sở ban ngành",IF(ISNUMBER(SEARCH("sở",$B9)),"Sở ban ngành",IF(ISNUMBER(SEARCH("thôn",$B9)),"Sở ban ngành",IF(ISNUMBER(SEARCH("xã",$B9)),"Sở ban ngành",IF(ISNUMBER(SEARCH("quân khu",$B9)),"Sở ban ngành",IF(ISNUMBER(SEARCH("cục",$B9)),"Sở ban ngành",IF(ISNUMBER(SEARCH("viện",$B9)),"Sở ban ngành",IF(ISNUMBER(SEARCH("quỹ",$B9)),"Sở ban ngành",IF(ISNUMBER(SEARCH("trung tâm",$B9)),"Sở ban ngành",IF(ISNUMBER(SEARCH("quân chủng",$B9)),"Sở ban ngành",IF(ISNUMBER(SEARCH("hội",$B9)),"Sở ban ngành", "Khác"))))))))))))))))))))))) -> Doanh nghiệp | J9: Bán hàng trực tiếp | K9: B | L9: =Data!$D9/10^6 -> 108.855
A10: BPC | B10: Công ty 19 | C10: DVKT | D10: 8925620 | E10: 45292 | F10: =MONTH(Data!$E10) -> 1 | G10: =YEAR(Data!$E10) -> 2024 | H10: Đông Nam Bộ | I10: =IF(ISNUMBER(SEARCH("Công ty",$B10)),"Doanh nghiệp",IF(ISNUMBER(SEARCH("Doanh nghiệp",$B10)),"Doanh nghiệp",IF(ISNUMBER(SEARCH("Tập đoàn",$B10)),"Doanh nghiệp", IF(ISNUMBER(SEARCH("Bệnh viện",$B10)),"Bệnh viện", IF(ISNUMBER(SEARCH("Ngân hàng",$B10)),"Ngân hàng",IF(ISNUMBER(SEARCH("trường",$B10)),"Trường học",IF(ISNUMBER(SEARCH("học viện",$B10)),"Trường học", IF(ISNUMBER(SEARCH("Bộ",$B10)),"Sở ban ngành",IF(ISNUMBER(SEARCH("Đoàn",$B10)),"Sở ban ngành",IF(ISNUMBER(SEARCH("Phòng",$B10)),"Sở ban ngành",IF(ISNUMBER(SEARCH("UBND",$B10)),"Sở ban ngành",IF(ISNUMBER(SEARCH("ủy ban",$B10)),"Sở ban ngành",IF(ISNUMBER(SEARCH("công an",$B10)),"Sở ban ngành",IF(ISNUMBER(SEARCH("sở",$B10)),"Sở ban ngành",IF(ISNUMBER(SEARCH("thôn",$B10)),"Sở ban ngành",IF(ISNUMBER(SEARCH("xã",$B10)),"Sở ban ngành",IF(ISNUMBER(SEARCH("quân khu",$B10)),"Sở ban ngành",IF(ISNUMBER(SEARCH("cục",$B10)),"Sở ban ngành",IF(ISNUMBER(SEARCH("viện",$B10)),"Sở ban ngành",IF(ISNUMBER(SEARCH("quỹ",$B10)),"Sở ban ngành",IF(ISNUMBER(SEARCH("trung tâm",$B10)),"Sở ban ngành",IF(ISNUMBER(SEARCH("quân chủng",$B10)),"Sở ban ngành",IF(ISNUMBER(SEARCH("hội",$B10)),"Sở ban ngành", "Khác"))))))))))))))))))))))) -> Doanh nghiệp | J10: Digital Marketing | K10: D | L10: =Data!$D10/10^6 -> 8.92562
A11: BPC | B11: Công ty 22 | C11: DVKT | D11: 8925620 | E11: 45292 | F11: =MONTH(Data!$E11) -> 1 | G11: =YEAR(Data!$E11) -> 2024 | H11: Đông Nam Bộ | I11: =IF(ISNUMBER(SEARCH("Công ty",$B11)),"Doanh nghiệp",IF(ISNUMBER(SEARCH("Doanh nghiệp",$B11)),"Doanh nghiệp",IF(ISNUMBER(SEARCH("Tập đoàn",$B11)),"Doanh nghiệp", IF(ISNUMBER(SEARCH("Bệnh viện",$B11)),"Bệnh viện", IF(ISNUMBER(SEARCH("Ngân hàng",$B11)),"Ngân hàng",IF(ISNUMBER(SEARCH("trường",$B11)),"Trường học",IF(ISNUMBER(SEARCH("học viện",$B11)),"Trường học", IF(ISNUMBER(SEARCH("Bộ",$B11)),"Sở ban ngành",IF(ISNUMBER(SEARCH("Đoàn",$B11)),"Sở ban ngành",IF(ISNUMBER(SEARCH("Phòng",$B11)),"Sở ban ngành",IF(ISNUMBER(SEARCH("UBND",$B11)),"Sở ban ngành",IF(ISNUMBER(SEARCH("ủy ban",$B11)),"Sở ban ngành",IF(ISNUMBER(SEARCH("công an",$B11)),"Sở ban ngành",IF(ISNUMBER(SEARCH("sở",$B11)),"Sở ban ngành",IF(ISNUMBER(SEARCH("thôn",$B11)),"Sở ban ngành",IF(ISNUMBER(SEARCH("xã",$B11)),"Sở ban ngành",IF(ISNUMBER(SEARCH("quân khu",$B11)),"Sở ban ngành",IF(ISNUMBER(SEARCH("cục",$B11)),"Sở ban ngành",IF(ISNUMBER(SEARCH("viện",$B11)),"Sở ban ngành",IF(ISNUMBER(SEARCH("quỹ",$B11)),"Sở ban ngành",IF(ISNUMBER(SEARCH("trung tâm",$B11)),"Sở ban ngành",IF(ISNUMBER(SEARCH("quân chủng",$B11)),"Sở ban ngành",IF(ISNUMBER(SEARCH("hội",$B11)),"Sở ban ngành", "Khác"))))))))))))))))))))))) -> Doanh nghiệp | J11: Bán hàng trực tiếp | K11: D | L11: =Data!$D11/10^6 -> 8.92562
A12: BPC | B12: Công ty 30 | C12: DVKT | D12: 8925620 | E12: 45292 | F12: =MONTH(Data!$E12) -> 1 | G12: =YEAR(Data!$E12) -> 2024 | H12: Đông Nam Bộ | I12: =IF(ISNUMBER(SEARCH("Công ty",$B12)),"Doanh nghiệp",IF(ISNUMBER(SEARCH("Doanh nghiệp",$B12)),"Doanh nghiệp",IF(ISNUMBER(SEARCH("Tập đoàn",$B12)),"Doanh nghiệp", IF(ISNUMBER(SEARCH("Bệnh viện",$B12)),"Bệnh viện", IF(ISNUMBER(SEARCH("Ngân hàng",$B12)),"Ngân hàng",IF(ISNUMBER(SEARCH("trường",$B12)),"Trường học",IF(ISNUMBER(SEARCH("học viện",$B12)),"Trường học", IF(ISNUMBER(SEARCH("Bộ",$B12)),"Sở ban ngành",IF(ISNUMBER(SEARCH("Đoàn",$B12)),"Sở ban ngành",IF(ISNUMBER(SEARCH("Phòng",$B12)),"Sở ban ngành",IF(ISNUMBER(SEARCH("UBND",$B12)),"Sở ban ngành",IF(ISNUMBER(SEARCH("ủy ban",$B12)),"Sở ban ngành",IF(ISNUMBER(SEARCH("công an",$B12)),"Sở ban ngành",IF(ISNUMBER(SEARCH("sở",$B12)),"Sở ban ngành",IF(ISNUMBER(SEARCH("thôn",$B12)),"Sở ban ngành",IF(ISNUMBER(SEARCH("xã",$B12)),"Sở ban ngành",IF(ISNUMBER(SEARCH("quân khu",$B12)),"Sở ban ngành",IF(ISNUMBER(SEARCH("cục",$B12)),"Sở ban ngành",IF(ISNUMBER(SEARCH("viện",$B12)),"Sở ban ngành",IF(ISNUMBER(SEARCH("quỹ",$B12)),"Sở ban ngành",IF(ISNUMBER(SEARCH("trung tâm",$B12)),"Sở ban ngành",IF(ISNUMBER(SEARCH("quân chủng",$B12)),"Sở ban ngành",IF(ISNUMBER(SEARCH("hội",$B12)),"Sở ban ngành", "Khác"))))))))))))))))))))))) -> Doanh nghiệp | J12: Digital Marketing | K12: D | L12: =Data!$D12/10^6 -> 8.92562
A13: QBH | B13: Công ty 31 | C13: DVKT | D13: 29880000 | E13: 45292 | F13: =MONTH(Data!$E13) -> 1 | G13: =YEAR(Data!$E13) -> 2024 | H13: Bắc Trung Bộ | I13: =IF(ISNUMBER(SEARCH("Công ty",$B13)),"Doanh nghiệp",IF(ISNUMBER(SEARCH("Doanh nghiệp",$B13)),"Doanh nghiệp",IF(ISNUMBER(SEARCH("Tập đoàn",$B13)),"Doanh nghiệp", IF(ISNUMBER(SEARCH("Bệnh viện",$B13)),"Bệnh viện", IF(ISNUMBER(SEARCH("Ngân hàng",$B13)),"Ngân hàng",IF(ISNUMBER(SEARCH("trường",$B13)),"Trường học",IF(ISNUMBER(SEARCH("học viện",$B13)),"Trường học", IF(ISNUMBER(SEARCH("Bộ",$B13)),"Sở ban ngành",IF(ISNUMBER(SEARCH("Đoàn",$B13)),"Sở ban ngành",IF(ISNUMBER(SEARCH("Phòng",$B13)),"Sở ban ngành",IF(ISNUMBER(SEARCH("UBND",$B13)),"Sở ban ngành",IF(ISNUMBER(SEARCH("ủy ban",$B13)),"Sở ban ngành",IF(ISNUMBER(SEARCH("công an",$B13)),"Sở ban ngành",IF(ISNUMBER(SEARCH("sở",$B13)),"Sở ban ngành",IF(ISNUMBER(SEARCH("thôn",$B13)),"Sở ban ngành",IF(ISNUMBER(SEARCH("xã",$B13)),"Sở ban ngành",IF(ISNUMBER(SEARCH("quân khu",$B13)),"Sở ban ngành",IF(ISNUMBER(SEARCH("cục",$B13)),"Sở ban ngành",IF(ISNUMBER(SEARCH("viện",$B13)),"Sở ban ngành",IF(ISNUMBER(SEARCH("quỹ",$B13)),"Sở ban ngành",IF(ISNUMBER(SEARCH("trung tâm",$B13)),"Sở ban ngành",IF(ISNUMBER(SEARCH("quân chủng",$B13)),"Sở ban ngành",IF(ISNUMBER(SEARCH("hội",$B13)),"Sở ban ngành", "Khác"))))))))))))))))))))))) -> Doanh nghiệp | J13: Bán hàng trực tiếp | K13: E | L13: =Data!$D13/10^6 -> 29.88
A14: VTU | B14: Công ty 50 | C14: ICT | D14: 97927923 | E14: 45292 | F14: =MONTH(Data!$E14) -> 1 | G14: =YEAR(Data!$E14) -> 2024 | H14: Đông Nam Bộ | I14: =IF(ISNUMBER(SEARCH("Công ty",$B14)),"Doanh nghiệp",IF(ISNUMBER(SEARCH("Doanh nghiệp",$B14)),"Doanh nghiệp",IF(ISNUMBER(SEARCH("Tập đoàn",$B14)),"Doanh nghiệp", IF(ISNUMBER(SEARCH("Bệnh viện",$B14)),"Bệnh viện", IF(ISNUMBER(SEARCH("Ngân hàng",$B14)),"Ngân hàng",IF(ISNUMBER(SEARCH("trường",$B14)),"Trường học",IF(ISNUMBER(SEARCH("học viện",$B14)),"Trường học", IF(ISNUMBER(SEARCH("Bộ",$B14)),"Sở ban ngành",IF(ISNUMBER(SEARCH("Đoàn",$B14)),"Sở ban ngành",IF(ISNUMBER(SEARCH("Phòng",$B14)),"Sở ban ngành",IF(ISNUMBER(SEARCH("UBND",$B14)),"Sở ban ngành",IF(ISNUMBER(SEARCH("ủy ban",$B14)),"Sở ban ngành",IF(ISNUMBER(SEARCH("công an",$B14)),"Sở ban ngành",IF(ISNUMBER(SEARCH("sở",$B14)),"Sở ban ngành",IF(ISNUMBER(SEARCH("thôn",$B14)),"Sở ban ngành",IF(ISNUMBER(SEARCH("xã",$B14)),"Sở ban ngành",IF(ISNUMBER(SEARCH("quân khu",$B14)),"Sở ban ngành",IF(ISNUMBER(SEARCH("cục",$B14)),"Sở ban ngành",IF(ISNUMBER(SEARCH("viện",$B14)),"Sở ban ngành",IF(ISNUMBER(SEARCH("quỹ",$B14)),"Sở ban ngành",IF(ISNUMBER(SEARCH("trung tâm",$B14)),"Sở ban ngành",IF(ISNUMBER(SEARCH("quân chủng",$B14)),"Sở ban ngành",IF(ISNUMBER(SEARCH("hội",$B14)),"Sở ban ngành", "Khác"))))))))))))))))))))))) -> Doanh nghiệp | J14: Digital Marketing | K14: F | L14: =Data!$D14/10^6 -> 97.927923
... A2700: NAN | B2700: Trường Trung Học Cơ Sở Quỳnh Long | C2700: ICT | D2700: 39254545 | E2700: 45627 | F2700: =MONTH(Data!$E2700) -> 12 | G2700: =YEAR(Data!$E2700) -> 2024 | H2700: Bắc Trung Bộ | I2700: =IF(ISNUMBER(SEARCH("Công ty",$B2700)),"Doanh nghiệp",IF(ISNUMBER(SEARCH("Doanh nghiệp",$B2700)),"Doanh nghiệp",IF(ISNUMBER(SEARCH("Tập đoàn",$B2700)),"Doanh nghiệp", IF(ISNUMBER(SEARCH("Bệnh viện",$B2700)),"Bệnh viện", IF(ISNUMBER(SEARCH("Ngân hàng",$B2700)),"Ngân hàng",IF(ISNUMBER(SEARCH("trường",$B2700)),"Trường học",IF(ISNUMBER(SEARCH("học viện",$B2700)),"Trường học", IF(ISNUMBER(SEARCH("Bộ",$B2700)),"Sở ban ngành",IF(ISNUMBER(SEARCH("Đoàn",$B2700)),"Sở ban ngành",IF(ISNUMBER(SEARCH("Phòng",$B2700)),"Sở ban ngành",IF(ISNUMBER(SEARCH("UBND",$B2700)),"Sở ban ngành",IF(ISNUMBER(SEARCH("ủy ban",$B2700)),"Sở ban ngành",IF(ISNUMBER(SEARCH("công an",$B2700)),"Sở ban ngành",IF(ISNUMBER(SEARCH("sở",$B2700)),"Sở ban ngành",IF(ISNUMBER(SEARCH("thôn",$B2700)),"Sở ban ngành",IF(ISNUMBER(SEARCH("xã",$B2700)),"Sở ban ngành",IF(ISNUMBER(SEARCH("quân khu",$B2700)),"Sở ban ngành",IF(ISNUMBER(SEARCH("cục",$B2700)),"Sở ban ngành",IF(ISNUMBER(SEARCH("viện",$B2700)),"Sở ban ngành",IF(ISNUMBER(SEARCH("quỹ",$B2700)),"Sở ban ngành",IF(ISNUMBER(SEARCH("trung tâm",$B2700)),"Sở ban ngành",IF(ISNUMBER(SEARCH("quân chủng",$B2700)),"Sở ban ngành",IF(ISNUMBER(SEARCH("hội",$B2700)),"Sở ban ngành", "Khác"))))))))))))))))))))))) -> Trường học | J2700: Digital Marketing | K2700: A | L2700: =Data!$D2700/10^6 -> 39.254545

Sheet Pivot
A3: Sum of Nguồn việc | F3: Row Labels | G3: Sum of Nguồn việc | I3: Row Labels | J3: Sum of Nguồn việc | O3: State | P3: Số lượng | R3: Row Labels | S3: Sum of Nguồn việc | U3: =TEXT(TODAY(), "DD/MM/YYYY") -> 11/08/2025
A4: 765873.47 | F4: Bệnh viện | G4: 4254.8859 | I4: AGG | J4: 6492.4351 | L4: {=_xlfn._xlws.FILTER(_xlfn.SORTBY(I4:J66, J4:J66, -1), I4:I66 <> "")} -> HNI | M4: 58864.912 | O4: An Giang | P4: =J4 -> 6492.4351 | R4: Bán hàng trực tiếp | S4: 385670.06 | T4: =S4/$S$6 -> 0.50356889
F5: Doanh nghiệp | G5: 620502.77 | I5: BDG | J5: 18169.265 | L5: HCM | M5: 48054.52 | O5: Ba Ria - Vung Tau | P5: =J5 -> 18169.265 | R5: Digital Marketing | S5: 380203.41 | T5: =S5/$S$6 -> 0.49643111
A6: Row Labels | B6: Sum of Nguồn việc | F6: Sở ban ngành | G6: 112764.22 | I6: BDH | J6: 6328.6192 | L6: VTU | M6: 39044.201 | O6: Bac Giang | P6: =J6 -> 6328.6192 | R6: Grand Total | S6: 765873.47
A7: CSDT | B7: 6934.0263 | F7: Trường học | G7: 27175.399 | I7: BGG | J7: 10077.914 | L7: QNM | M7: 38712.175 | O7: Bac Kan | P7: =J7 -> 10077.914
A8: DVKT | B8: 60910.776 | F8: Ngân hàng | G8: 1176.199 | I8: BKN | J8: 7482.8185 | L8: DNI | M8: 37253.054 | O8: Bac Lieu | P8: =J8 -> 7482.8185
A9: ICT | B9: 198681.76 | F9: Grand Total | G9: 765873.47 | I9: BLU | J9: 1358.8011 | L9: TBH | M9: 36020.359 | O9: Bac Ninh | P9: =J9 -> 1358.8011
A10: ME | B10: 207178.38 | I10: BNH | J10: 21093.92 | L10: TNN | M10: 30017.941 | O10: Ben Tre | P10: =J10 -> 21093.92
A11: NLMT | B11: 267832.92 | I11: BPC | J11: 3365.7312 | L11: QTI | M11: 29579.392 | O11: Binh Dinh | P11: =J11 -> 3365.7312
A12: Smarthome | B12: 24335.613 | I12: BTE | J12: 3772.3718 | L12: NAN | M12: 23353.014 | O12: Binh Duong | P12: =J12 -> 3772.3718
A13: Grand Total | B13: 765873.47 | F13: Row Labels | G13: Sum of Nguồn việc | I13: BTN | J13: 9778.0371 | L13: PTO | M13: 21166.138 | O13: Binh Phuoc | P13: =J13 -> 9778.0371
F14: A | G14: 48452.321 | I14: CBG | J14: 12146.813 | L14: BNH | M14: 21093.92 | O14: Binh Thuan | P14: =J14 -> 12146.813
A15: Sum of Nguồn việc | B15: Column Labels | F15: B | G15: 71237.085 | I15: CMU | J15: 2185.0733 | L15: BDG | M15: 18169.265 | O15: Ca Mau | P15: =J15 -> 2185.0733
A16: Row Labels | B16: 2024 | C16: 2025 | D16: Grand Total | F16: C | G16: 73191.06 | I16: CTO | J16: 7180.0828 | L16: TGG | M16: 17777.69 | O16: Can Tho | P16: =J16 -> 7180.0828
A17: 1 | B17: 46229.978 | C17: 66868.99 | D17: 113098.97 | F17: D | G17: 248566.97 | I17: DBN | J17: 7092.8287 | L17: DNG | M17: 16796.271 | O17: Cao Bang | P17: =J17 -> 7092.8287
A18: 2 | B18: 29340.655 | C18: 78898.315 | D18: 108238.97 | F18: E | G18: 90030.551 | I18: DCN | J18: 10562.579 | L18: NDH | M18: 15985.129 | O18: Da Nang | P18: =J18 -> 10562.579
A19: 3 | B19: 25478.977 | C19: 19766.52 | D19: 45245.496 | F19: F | G19: 84792.412 | I19: DLK | J19: 1622.8123 | L19: LSN | M19: 15218.321 | O19: Dak Lak | P19: =J19 -> 1622.8123
A20: 4 | B20: 44719.749 | D20: 44719.749 | F20: G | G20: 5904.709 | I20: DNG | J20: 16796.271 | L20: GLI | M20: 13394.809 | O20: Dak Nong | P20: =J20 -> 16796.271
A21: 5 | B21: 34758.736 | D21: 34758.736 | F21: H | G21: 11885.482 | I21: DNI | J21: 37253.054 | L21: VPC | M21: 13241.833 | O21: Dien Bien Phu | P21: =J21 -> 37253.054
A22: 6 | B22: 27806.668 | D22: 27806.668 | F22: I | G22: 1908.2089 | I22: DTP | J22: 3225.2525 | L22: HUE | M22: 12500.856 | O22: Dong Nai | P22: =J22 -> 3225.2525
A23: 7 | B23: 35727.38 | D23: 35727.38 | F23: K | G23: 24256.627 | I23: GLI | J23: 13394.809 | L23: CBG | M23: 12146.813 | O23: Dong Thap | P23: =J23 -> 13394.809
A24: 8 | B24: 45276.315 | D24: 45276.315 | F24: L | G24: 7997.0261 | I24: HBH | J24: 1926.1303 | L24: KHA | M24: 11129.99 | O24: Gia Lai | P24: =J24 -> 1926.1303
A25: 9 | B25: 31136.262 | D25: 31136.262 | F25: M | G25: 38760.772 | I25: HCM | J25: 48054.52 | L25: DCN | M25: 10562.579 | O25: Ha Giang | P25: =J25 -> 48054.52
A26: 10 | B26: 65701.014 | D26: 65701.014 | F26: N | G26: 3109.3855 | I26: HDG | J26: 4808.0657 | L26: PYN | M26: 10149.917 | O26: Ha Nam | P26: =J26 -> 4808.0657
A27: 11 | B27: 94407.084 | D27: 94407.084 | F27: O | G27: 18362.554 | I27: HGG | J27: 7385.6016 | L27: BGG | M27: 10077.914 | O27: Ha Noi | P27: =J27 -> 7385.6016
A28: 12 | B28: 119756.83 | D28: 119756.83 | F28: P | G28: 8153.211 | I28: HNI | J28: 58864.912 | L28: BTN | M28: 9778.0371 | O28: Ha Tinh | P28: =J28 -> 58864.912
A29: Grand Total | B29: 600339.65 | C29: 165533.83 | D29: 765873.47 | F29: Q | G29: 9024.2617 | I29: HNM | J29: 9591.319 | L29: TQG | M29: 9619.7466 | O29: Hai Duong | P29: =J29 -> 9591.319
F30: T | G30: 8425.9238 | I30: HPG | J30: 7935.2906 | L30: HNM | M30: 9591.319 | O30: Hai Phong | P30: =J30 -> 7935.2906
F31: R | G31: 20 | I31: HTH | J31: 4869.3244 | L31: HUG | M31: 9576.95 | O31: Hau Giang | P31: =J31 -> 4869.3244
F32: U | G32: 11684.002 | I32: HUE | J32: 12500.856 | L32: LCI | M32: 8310.3981 | O32: Ho Chi Minh | P32: =J32 -> 12500.856
F33: W | G33: 110.915 | I33: HUG | J33: 9576.95 | L33: SLA | M33: 8113.1165 | O33: Hoa Binh | P33: =J33 -> 9576.95
F34: Grand Total | G34: 765873.47 | I34: HYN | J34: 2725.5278 | L34: HPG | M34: 7935.2906 | O34: Hung Yen | P34: =J34 -> 2725.5278
I35: KGG | J35: 3685.129 | L35: BKN | M35: 7482.8185 | O35: Khanh Hoa | P35: =J35 -> 3685.129
I36: KHA | J36: 11129.99 | L36: HGG | M36: 7385.6016 | O36: Kien Giang | P36: =J36 -> 11129.99
I37: KTM | J37: 1922.1125 | L37: QNI | M37: 7271.4198 | O37: Kon Tum | P37: =J37 -> 1922.1125
I38: LAN | J38: 3720.8367 | L38: THA | M38: 7220.2805 | O38: Lai Chau | P38: =J38 -> 3720.8367
I39: LCI | J39: 8310.3981 | L39: CTO | M39: 7180.0828 | O39: Lam Dong | P39: =J39 -> 8310.3981
I40: LCU | J40: 2820.4873 | L40: DBN | M40: 7092.8287 | O40: Lang Son | P40: =J40 -> 2820.4873
I41: LDG | J41: 5822.3394 | L41: QBH | M41: 6916.81 | O41: Lao Cai | P41: =J41 -> 5822.3394
I42: LSN | J42: 15218.321 | L42: AGG | M42: 6492.4351 | O42: Long An | P42: =J42 -> 15218.321
...

Sheet Các bước
A1: 1. Vào bảng data gốc, ấn Ctrl T để tạo Table
A2: (Để hủy định dạng Table: Bôi đen Table => Chuột phải => Table => Convert to Range)
A3: 2. Ấn vào 1 vị trí bất kỳ của Table => Thẻ Insert chọn Pivot => Tạo các bảng Pivot theo mong muốn
A4: 3. Tạo các khung báo cáo
A5: 4. Tạo tiêu đề BC
A6: 5. Link nội dung BC vào các khung qua Textbox (lưu ý không viết lệnh trong textbox mà viết lệnh trên thanh formula)
A7: 6. Vẽ biểu đồ bên sheet pivot
A8: - Ấn vào 1 bảng pivot => Chọn Analyze => PivotChart
A9: - Vẽ và tuỳ chỉnh biểu đồ => Ctrl X => Paste sang Sheet báo cáo
A10: - Xóa các mục như “Sum of Nguồn việc” (tên trường dữ liệu) và bộ lọc tỉnh => Nhấp vào biểu đồ => Trên thanh PivotChart Analyze (hoặc Analyze tùy bản Excel) => Chọn Field Buttons → Hide All
A11: - Tắt Grand Total trong PivotTable => Chọn vào PivotTable => Vào tab PivotTable Analyze (hoặc Design tùy phiên bản Excel) => Chọn Grand Totals → Off for Rows and Columns
A12: 7. Tạo bộ lọc cho báo cáo
... A15: - Chọn vào 1 bộ lọc => Chọn Report Connections => Chọn tất cả các bảng pivot => Làm lần lượt cho từng bộ lọc

Sheet Mã tỉnh
A1: Mã tỉnh | B1: Tên tỉnh | C1: Ten Tinh
A3: QTI | B3: Quảng Trị | C3: Quang Tri
A4: BTN | B4: Bình Thuận | C4: Binh Thuan
A5: KTM | B5: Kon Tum | C5: Kon Tum
A6: HGG | B6: Hà Giang | C6: Ha Giang
A7: NAN | B7: Nghệ An | C7: Nghe An
A8: HUG | B8: Hậu Giang | C8: Hau Giang
A9: HYN | B9: Hưng Yên | C9: Hung Yen
A10: VPC | B10: Vĩnh Phúc | C10: Vinh Phuc
A11: DNI | B11: Đồng Nai | C11: Dong Nai
A12: QNM | B12: Quảng Nam | C12: Quang Nam
A13: NDH | B13: Nam Định | C13: Nam Dinh
... A65: NTN | B65: Ninh Thuận | C65: Ninh Thuan
